<?xml version="1.0"?>
<robot name="arm">

  <material name="gray">
    <color rgba="0.5 0.5 0.5 1.0"/>
  </material>
  
  <material name="blue">
    <color rgba="0.2 0.4 0.8 1.0"/>
  </material>
  
  <material name="red">
    <color rgba="0.8 0.2 0.2 1.0"/>
  </material>
  
  <material name="green">
    <color rgba="0.2 0.8 0.2 1.0"/>
  </material>
  
  <material name="orange">
    <color rgba="1.0 0.5 0.0 1.0"/>
  </material>
  
  <material name="yellow">
    <color rgba="0.9 0.9 0.2 1.0"/>
  </material>
  
  <material name="purple">
    <color rgba="0.6 0.2 0.8 1.0"/>
  </material>

  <link name="plate">
    <visual>
      <geometry>
        <cylinder length="0.029471" radius="0.0885"/>
      </geometry>
      <material name="gray"/>
    </visual>
    <collision>
      <geometry>
        <cylinder length="0.029471" radius="0.0885"/>
      </geometry>
    </collision>
    <inertial>
      <mass value="0.5"/>
      <origin xyz="0 0 0" rpy="0 0 0"/>
      <inertia ixx="0.001" ixy="0.0" ixz="0.0" iyy="0.001" iyz="0.0" izz="0.001"/>
    </inertial>
  </link>

  <link name="shoulder_base">
    <visual>
      <geometry>
        <cylinder length="0.061043" radius="0.05"/>
      </geometry>
      <origin rpy="0 0 0" xyz="0 0 0.0305215"/>
      <material name="blue"/>
    </visual>
    <collision>
      <geometry>
        <cylinder length="0.061043" radius="0.05"/>
      </geometry>
      <origin rpy="0 0 0" xyz="0 0 0.0305215"/>
    </collision>
    <inertial>
      <mass value="0.8"/>
      <origin xyz="0 0 0.0305215" rpy="0 0 0"/>
      <inertia ixx="0.002" ixy="0.0" ixz="0.0" iyy="0.002" iyz="0.0" izz="0.001"/>
    </inertial>
  </link>

  <joint name="shoulder_pan" type="revolute">
    <parent link="plate"/>
    <child link="shoulder_base"/>
    <origin xyz="0 0 0.0147355" rpy="0 0 0"/>
    <axis xyz="0 0 1"/>
    <limit lower="-3.14" upper="3.14" effort="10.0" velocity="2.0"/>
    <dynamics damping="0.1" friction="0.05"/>
  </joint>

  <link name="shoulder_arm">
    <visual>
      <geometry>
        <box size="0.05 0.03 0.3"/>
      </geometry>
      <origin xyz="0 0 0.15" rpy="0 0 0"/>
      <material name="red"/>
    </visual>
    <collision>
      <geometry>
        <box size="0.05 0.03 0.3"/>
      </geometry>
      <origin xyz="0 0 0.15" rpy="0 0 0"/>
    </collision>
    <inertial>
      <mass value="0.6"/>
      <origin xyz="0 0 0.15" rpy="0 0 0"/>
      <inertia ixx="0.0046" ixy="0.0" ixz="0.0" iyy="0.0047" iyz="0.0" izz="0.0003"/>
    </inertial>
  </link>
  
  <joint name="shoulder_tilt" type="revolute">
    <parent link="shoulder_base"/>
    <child link="shoulder_arm"/>
    <origin xyz="0 0 0.061043" rpy="0 0 0"/>
    <axis xyz="0 1 0"/>
    <limit lower="-1.57" upper="1.57" effort="10.0" velocity="2.0"/>
    <dynamics damping="0.1" friction="0.05"/>
  </joint>

  <link name="forearm">
    <visual>
      <geometry>
        <box size="0.05 0.03 0.558"/>
      </geometry>
      <origin xyz="0 0 0.279" rpy="0 0 0"/>
      <material name="green"/>
    </visual>
    <collision>
      <geometry>
        <box size="0.05 0.03 0.558"/>
      </geometry>
      <origin xyz="0 0 0.279" rpy="0 0 0"/>
    </collision>
    <inertial>
      <mass value="0.5"/>
      <origin xyz="0 0 0.279" rpy="0 0 0"/>
      <inertia ixx="0.013" ixy="0.0" ixz="0.0" iyy="0.013" iyz="0.0" izz="0.0002"/>
    </inertial>
  </link>

  <joint name="elbow" type="revolute">
    <parent link="shoulder_arm"/>
    <child link="forearm"/>
    <origin xyz="0 -0.03 0.275" rpy="0 0 0"/>
    <axis xyz="0 1 0"/>
    <limit lower="-3.14" upper="3.14" effort="8.0" velocity="2.0"/>
    <dynamics damping="0.1" friction="0.05"/>
  </joint>

  <link name="forearm_tip">
    <visual>
        <geometry>
            <sphere radius="0.01"/>
        </geometry>
        <material name="purple"/>
    </visual>
    <collision>
        <geometry>
            <sphere radius="0.01"/>
        </geometry>
    </collision>
    <inertial>
        <mass value="0.001"/>
        <origin xyz="0 0 0" rpy="0 0 0"/>
        <inertia ixx="0.000001" ixy="0.0" ixz="0.0" iyy="0.000001" iyz="0.0" izz="0.000001"/>
    </inertial>
</link>

<joint name="forearm_tip_joint" type="fixed">
    <parent link="forearm"/>
    <child link="forearm_tip"/>
    <origin xyz="0 0 0.558" rpy="0 0 0"/>  <!-- At end of forearm -->
</joint>

  <link name="wrist_pitch_link">
    <visual>
      <geometry>
        <box size="0.04 0.06 0.04"/>
      </geometry>
      <origin xyz="0 0 0.02" rpy="0 0 0"/>
      <material name="orange"/>
    </visual>
    <collision>
      <geometry>
        <box size="0.04 0.06 0.04"/>
      </geometry>
      <origin xyz="0 0 0.02" rpy="0 0 0"/>
    </collision>
    <inertial>
      <mass value="0.2"/>
      <origin xyz="0 0 0.02" rpy="0 0 0"/>
      <inertia ixx="0.0001" ixy="0.0" ixz="0.0" iyy="0.00001" iyz="0.0" izz="0.0001"/>
    </inertial>
  </link>
  
  <joint name="wrist_pitch" type="revolute">
    <parent link="forearm"/>
    <child link="wrist_pitch_link"/>
    <origin xyz="0 0 0.558" rpy="0 0 0"/>
    <axis xyz="0 1 0"/>
    <limit lower="-1.57" upper="1.57" effort="5.0" velocity="3.0"/>
    <dynamics damping="0.05" friction="0.02"/>
  </joint>

  <link name="wrist_roll_link">
    <visual>
      <geometry>
        <box size="0.035 0.035 0.028"/>
      </geometry>
      <origin xyz="0 0 0.014" rpy="0 0 0"/>
      <material name="yellow"/>
    </visual>
    <collision>
      <geometry>
        <box size="0.035 0.035 0.028"/>
      </geometry>
      <origin xyz="0 0 0.014" rpy="0 0 0"/>
    </collision>
    <inertial>
      <mass value="0.15"/>
      <origin xyz="0 0 0.014" rpy="0 0 0"/>
      <inertia ixx="0.00005" ixy="0.0" ixz="0.0" iyy="0.00005" iyz="0.0" izz="0.00004"/>
    </inertial>
  </link>
  
  <joint name="wrist_roll" type="revolute">
    <parent link="wrist_pitch_link"/>
    <child link="wrist_roll_link"/>
    <origin xyz="0 0 0.04" rpy="0 0 0"/>
    <axis xyz="0 0 1"/>
    <limit lower="-3.14" upper="3.14" effort="5.0" velocity="3.0"/>
    <dynamics damping="0.05" friction="0.02"/>
  </joint>

  <link name="end_effector">
    <visual>
      <geometry>
        <cylinder length="0.01" radius="0.02"/>
      </geometry>
      <origin xyz="0 0 0.005" rpy="0 0 0"/>
      <material name="purple"/>
    </visual>
    <collision>
      <geometry>
        <cylinder length="0.01" radius="0.02"/>
      </geometry>
      <origin xyz="0 0 0.005" rpy="0 0 0"/>
    </collision>
    <inertial>
      <mass value="0.05"/>
      <origin xyz="0 0 0.005" rpy="0 0 0"/>
      <inertia ixx="0.00001" ixy="0.0" ixz="0.0" iyy="0.00001" iyz="0.0" izz="0.00001"/>
    </inertial>
  </link>
  
  <joint name="end_effector_mount" type="fixed">
    <parent link="wrist_pitch_link"/>
    <child link="end_effector"/>
    <origin xyz="0 0 0.028" rpy="0 0 0"/>
  </joint>

</robot>