<?xml version="1.0"?>
<robot name="wheel" xmlns:xacro="http://ros.org/wiki/xacro">
  <xacro:macro name="wheel" params="prefix:=^ side:=^ end:=^">
    <!-- WHEEL PROPERTIES -->
      <xacro:property name="track_width" value="0.1" />
      <xacro:property name="wheel_radius" value="0.05" />
      <xacro:property name="wheel_mass" value="1.0" />
      <xacro:property name="wheel_base" value="1.0" />
      
    <link name="${prefix}${end}_${side}_wheel">
      <inertial>
        <xacro:if value="${side == 'left'}">
          <origin xyz="0.0 0.125  0.0" rpy="0.0 0.0 0"/>
        </xacro:if>
        <xacro:if value="${side == 'right'}">
          <origin xyz="0.0 -0.125  0.0" rpy="0.0 0.0 0.0"/>
        </xacro:if>
        <mass value="1.0"/>        
        <inertia ixx="0.04" iyy="0.02" izz="0.02" ixy="0.0" iyz="0.0" ixz="0.0"/>
      </inertial>

      <visual>
        <xacro:if value="${side == 'left'}">
          <origin xyz="0.0 0.125  0.0" rpy="0.0 0.0 ${pi}"/>
        </xacro:if>
        <xacro:if value="${side == 'right'}">
          <origin xyz="0.0 -0.125  0.0" rpy="0.0 0.0 0.0"/>
        </xacro:if>
        <geometry>
          <mesh scale="0.1 0.1 0.1" filename="file://$(find perseus_description)/meshes/wheel.dae"/>
        </geometry>
      </visual>

      <collision>
        <xacro:if value="${side == 'left'}">
          <origin xyz="0.0 0.0 0.0" rpy="0.0 0.0 ${pi}"/>
        </xacro:if>
        <xacro:if value="${side == 'right'}">
          <origin xyz="0.0 0.0 0.0" rpy="0.0 0.0 0.0"/>
        </xacro:if>
        <geometry>
          <mesh scale="0.1 0.1 0.1" filename="file://$(find perseus_description)/meshes/wheel.dae"/>
        </geometry>
      </collision>
    </link>
    <!-- we need to use the gazebo tag to add in properties normally only found in SDF files -->
    <gazebo reference="${prefix}${end}_${side}_wheel">
      <!-- TODO: Fix the material tag (this isn't the proper way to do it, and spits out warnings) -->
      <material>Gazebo/Orange</material>
      <!-- see http://sdformat.org/spec?ver=1.12&elem=collision -->
      <collision>
        <surface>
            <friction>
                <ode>
                    <!--
                    In this case, the wheels need lower sideways than forwards coefficients of friction
                    so that the rover can turn (skid steer) -->
                    <!-- forward coefficient of friction -->
                    <mu>1</mu>
                    <!-- perpendicular coefficient of friction -->
                    <mu2>0.3</mu2>
                    <!--
                    However, since mu/mu2 are normally relative to world coordinates,
                    the rover would only be able to turn 90 degrees either way before they swapped, making turning impossible.
                    To solve this, we need to specify the direction that mu/mu2 are relative to.
                    -->
                    <fdir1>1 0 0</fdir1>
                </ode>
            </friction>
        </surface>
      </collision>
    </gazebo>

    <joint name="${prefix}${end}_${side}_wheel_joint" type="continuous">
      <xacro:if value="${side == 'left'}">
        <axis xyz="0 1 0" rpy="0 0 0"/>
      </xacro:if>
      <xacro:if value="${side == 'right'}">
        <axis xyz="0 1 0" rpy="0 0 0"/>
      </xacro:if>
      <parent link="${prefix}${end}_${side}_motor"/>
      <child link="${prefix}${end}_${side}_wheel"/>
      <origin xyz="0.125 0.0 0.0" rpy="0.0 0.0 0"/>
      <dynamics damping="0.2" friction="0.3"/>
    </joint>
  </xacro:macro>
</robot>