<?xml version="1.0"?>
<robot name="wheel" xmlns:xacro="http://ros.org/wiki/xacro">
  <xacro:macro name="wheel" params="prefix:=^ side:=^ end:=^">
    <link name="${prefix}${end}_${side}_wheel">
      <inertial>
        <origin xyz="0.0 0.0 0.0" rpy="0.0 0.0 0.0"/>
        <mass value="1.0"/>
        <inertia ixx="0.051473" iyy="0.029155" izz="0.029154" ixy="0.0" iyz="0.0" ixz="0.0"/>
      </inertial>

      <visual>
        <origin xyz="0.0 0.0 0.0" rpy="0.0 0.0 0.0"/>
        <geometry>
          <mesh scale="0.1 0.1 0.1" filename="file://$(find perseus_description)/meshes/wheel.dae"/>
        </geometry>
      </visual>

      <collision>
        <origin xyz="0.0 -0.015 0.0" rpy="1.570796 0.0 0.0"/>
        <geometry>
          <cylinder length="0.115" radius="0.145" />
        </geometry>
      </collision>
    </link>

    <joint name="${prefix}${end}_${side}_wheel_joint" type="continuous">
      <xacro:if value="${side == 'left'}">
        <axis xyz="0 1 0" rpy="0 0 0"/>
      </xacro:if>
      <xacro:if value="${side == 'right'}">
        <axis xyz="0 -1 0" rpy="0 0 0"/>
      </xacro:if>
      <parent link="${prefix}${end}_${side}_motor"/>
      <child link="${prefix}${end}_${side}_wheel"/>
      <origin xyz="-0.125 0.0 0.0" rpy="0.0 0.0 ${-pi/2}"/>
      <dynamics damping="1.0" friction="1.0"/>
    </joint>
  </xacro:macro>
</robot>